---
title: "[C++] Chapter.14 예외처리"
date: 2022-09-24 22:20:19 +0900
categories: [Language ,C++]
tags: [c++]
---
<hr>


## 예외처리의 기본
```cpp
// 예외 처리의 기본
// Exception Handing
#include <iostream>
#include <string>
#include <fstream>
#include <algorithm>
#include <cmath>

using namespace std;

//ch가 존재하는 문자열인지 확인 하는 함수
int findFirstChar(const char * string, char ch)
{
    for (std::size_t idx = 0; idx < strlen(string); ++idx) {
        if(string[idx] == ch)
            return idx;
    }
    
    //ch가 존재하지않는다면 -1 반환
    //예외처리 부분
    return -1;
}

double divide(int x, int y, bool &success)
{
    //0으로 나눌수없으므로 0.0을 반환
    if(y == 0)
    {
        success = false;
        return 0.0;
    }
    
    success = true;
    return static_cast<double>(x) / y;
}

int main() {
    //이번에는 예외처리에 대해 알아보자
    
    //좋은 프로그래머가 되기 위해 비정상적인 상황에 대해 안정적으로 실행이 되도록 만들어야 한다.
    //비정상적인 상황, 즉 예외적인 상황에 처리를 하는것을 예외처리라고 한다.
    //이번에는 기본적인 방법에 대해 알아보자
    
    
    bool success;
    double result = divide(5, 3, success);
    
    if(!success)
        std::cerr << "An Error occurred" << std::endl;      //오류 발생시 오류문구 출력
    else
        std::cout << "Result is " << result << std::endl;   //정상 작동시 결과 값 출력
    
    std::ifstream input_file("temp.txt");
    //파일 존재 유무 확인
    if(!input_file)
        std::cerr << "Cannot open file" << endl;    //파일이 없는경우 오류 문구 출력
    
    //이 예외처리 방식은 깔끔하지 않아보이지만 전통적인 C++방식으로는 이런식으로 많이 작성했다.
    //1. 퍼포먼스 측면에서 좋다.
    //2. 대체방법이 없었다.
    
    //다음에 배울 예외처리는 관점이 약간 달라진다.
    //다음에 배울 throw, try-catch방식은 깔끔해보이지만
    //퍼포먼스가 낮아진다.
    //퍼포먼스 중요한 경우 잘 사용하지 않는다.
    
    
    //예외처리를 사용하는경우
    //예측할수없는경우
    //서버의 경우 - 네트워크의 경우 - 갑자기 다운 되는 경우
    
    //예외처리를 안사용하는 분야도 존재하지만, 사용을 해야한다면 반드시 모든 오류 상황에 대해 예외처리를 해주어야한다.
    
    
    //기초적인 문법
    //try, catch, throw
    
    //throw - 오류를 던진다!
    
    //catch - 오류를 받는다!
    
    double x;
    cin >> x;
    
    try
    {
        if(x < 0.0) throw std::string("Negative input");
        //음수의 경우 오류 메시지를 날려준다.
        
        cout << sqrt(x) << endl;
    }
    //throw된 정보를 받는다.
    catch(std::string error_message)
    {
        //error_message에 throw로 날려준 string값을 catch하여 가져온다.
        cout << error_message << endl;
    }
    
    
    //주의사항
    //auto casting이 안된다.
    //throw와 오류를 받는 catch에 자료형이 같게 만들어줘야한다.
    
    
    try {
        throw -1.0;
        //throw -1.0; 인경우 double형이므로 catch에서 오류 발생
    }
    catch (int x) {
        cout << "Catch integer" << x  << endl;
    }
    catch (double x) {
        cout << "Catch double" << x  << endl;
    }
    catch(std::string error_message)
    {
        //error_message에 throw로 날려준 string값을 catch하여 가져온다.
        cout << error_message << endl;
    }
    //catch문이 여러개를 사용할수있다.
    //해당 오류에 관한 자료형의 catch가 없는경우 오류를 받아줄수있는곳이 없으므로 오류가 컴파일 오류가 발생한다.
    //throw와 catch의 자료형 타입이 같아야한다.
    
    return 0;
}
```

## 예외처리와 스택 되감기
```cpp
// 예외처리와 스택 되감기
// stack Unwinding

#include <iostream>

using namespace std;
//추가 문법
//void last() throw(int) exception specifier
//exception specifier
//함수 정의,선언시
//throw(data type)을 붙여주면
//data type에 대한 예외처리를 할수도있다.라고 알려주는것이다.
//항상 data type에 맞춘다는 문맥이 아니라 할 수 있다 라는 문맥이 강하다.
//불필요한것이 아닌가? 라는 견해가 많다고 한다.
//()에 아무것도 없는경우 이 함수는 throw를 하지않을것이다라는 험수를 구현하는것이다.

void last()
{
    cout << "last" << endl;
    cout << "Throws exception" << endl;
    
    throw -1;
    //-1인 경우 디버그로 찍어보면 스탭으로 찍어보면 throw이후 first를 출력한다.
    //frist를 출력하는 이유를 알아보자
    
    cout << "End last" << endl;
}


void third()
{
    cout << "third" << endl;
    
    last();
    //last에서 throw발생후 여기를 와서 catch를 찾으니 없어서 스택에서 unwinding발생
    //thrid를 호출한 second로 돌아감
    
    
    //오류를 잡지 못해 실행 안함
    cout << "End third" << endl;
}

void second()
{
    cout << "second" << endl;
    
    try {
        third();
    } catch (double) { //unwinding에 의해 second에 진입후 catch를 만났는데 throw값이 int type이므로 double type이므로 무시하고 second를 호출한 first로 넘어간다.
        cerr << "second caught double exception" << endl;
    }
    
    //오류를 잡지 못해 실행 안함
    cout << "End second" << endl;
}

void first()
{
    cout << "first" << endl;
    
    try {
        second();
    } catch (int) { //unwinding에 의해 second의 catch 조건이 double이므로 무시하고 first() catch에 도착한후 int type인것을 체크하고 같은 type이므로 catch실행
        cerr << "first caught int exception" << endl;
    }
    
    //오류잡고 나서 다음 코드실행
    cout << "End first" << endl;
}


int main() {
    //함수가 함수를 호출하는 구조가 구현이 된다면 스택에 함수가 쌓일것이다.
    //이러한 구조에서 예외처리를 하게 되면 스택이 되감아가면서 예외를 어디서 catch를 해야하는지 찾는다.
    //이러한 행위를 스택 되감기(Stack Unwinding)라고 한다.
    
    
    cout << "Start" << endl;
    
    try {
        first();
    } catch (int) {
        
        //cout, cerr, clog의 차이는 거의없다.
        //방송 채널에 비유해서 생각하면 된다.
        //cout - 출력을 버퍼에 담고 바로 출력 안하는 경우가 존재한다. 예시 - endl과 '\n'를 사용할때의차이
        //cerr - 출력을 버퍼를 통하지않고 endl과 '\n'가 없어도 출력한다.
        //clog - 기록용
        cerr << "main caught int exception" << endl;
    }
    
    //가능한 발생가능한 오류들에 대해 예외처리를 하였지만, 진짜 생각지도 못한 경우에 오류가 발생하는경우 처리가 안되어 런타임에러가 발생한다.
    //예제로 설명을 하자면 int error, double error 예외상황에 대해 예외처리를하였지만, 생각지도못한 char type이 나온다면 어떻게 해야하는가?
    //이런 경우에 대한 최후의 보루같은 방식이 존재한다.
    
    
    //uncaught exceptions
    //잡지못한 오류를 잡는 방법
    catch(...)  //catch-all handler
    {
        cerr << "main caught ellipses exception" << endl;
    }
    //모든 오류를 잡는다.
    //최후의 보루방법
    
    
    
    
    cout << "End main" << endl;
    return 0;
}
```
## 예외 클래스와 상속
```cpp
// 예외 클래와 상속

#include <iostream>

using namespace std;

//예외 처리 클래스
class Exception
{
public:
    void report()
    {
        cerr << "Exception report" << endl;
    }
};

class ArrayExcption : public Exception
{
public:
    void report()
    {
        cerr << "Array Exception" << endl;
    }
};

class MyArray
{
private:
    int m_data[5];
    
public:
    int & operator [] (const int & idx)
    {
        //기본 자료형의 throw 방식
        //if (idx < 0 || idx >= 5) throw -1;
    
        //class throw 방식
        if (idx < 0 || idx >= 5) throw ArrayExcption();
        //Exception의 객체를 만들어서 던져주는 형식
        return m_data[idx];
    }
};

void doSomething()
{
    MyArray my_arr;
    
    try {
        my_arr[100];
    } catch (const int & x) {
        cerr << "Exception " << x << endl;
    }
//    catch (Exception & e) {
//        e.report();
//    }
//    catch (ArrayExcption & e) {
//        e.report();
//    }
    //객체 잘림으로 인하여 Exception.report()가 실행이 된다.
    //ArrayExcption이 발생해야하지만, 이미 Excepion에서 먼저 잡혀서 Exception.report()가 실행이 된다.
    //대응 방법
    catch (ArrayExcption & e) {
        cout << "doSomething()" << endl;
        e.report();
        throw e;
        //rethrow main()에서 받기위한 throw
    }
    catch (Exception & e) {
        cout << "doSomething()" << endl;
        e.report();
    }
    //두개의 위치를바꿔준다.
    
}

int main() {
    //이번에는 예외클래스에 대해 알아보자
    //지금까지는 기본자료형에 관하여 throw하는것을 배웟다면 이번에는 사용자 정의 자료형으로 throw를 해보자
    
    doSomething();
    
    //catch에서 받는 작업들을 정리 하기위해 예외 클래스를 만들 수 있다.
    
    
    //주의사항 예외처리 클래스를 상속 받을떄 주의 사항이 몇가지 발생한다.
    
    
    try {
        doSomething();
    } catch (ArrayExcption & e) {
        //doSomething()에서 이미 오류가 잡혀서 여기서 예외처리를 하지않는다.
        //여기서도 예외처리를 무조건 해야한다면 어떻게 해야하는가?
        //doSomething()에서 catch한것을 다시 throw해줄수있다.
        //rethrow라고 부른다.
        cout << "main()" << endl;
        e.report();
    } catch(Exception & e) {
        cout << "main()" << endl;
        e.report();
    }
        
    
    return 0;
}
```
## exception 소개
```cpp
// exception 소개

#include <iostream>
#include <exception>
#include <string>

using namespace std;

//
class CustomException : public exception
{
public:
    //exception의 what()을 오버라이딩
    //사용자 정의 예외처리 클래스에서도 what을 작동하기 위해 오버라이딩해준다.
    const char * what() const noexcept override
    {
        return "Custom exception";
    }
    
    //noexcept C++11이상부터는 붙여줘야한다고 한다.
    
};

int main() {
    //이번에는 STL에 존재하는 Exception class에서 대해 알아보자
    //다양한 경우의 예외처리에 대해 이미 STL에 구현이 되어있다.
    //구현하는 시간을 단축하기위해 STL의 Exception class를 사용하자
    
    
    try {
        //이미 구현 되어있는 string의 exception 확인방법
//        string s;
//        s.resize(-1);
        
        //execption만 가져다 사용하는방법
//        throw runtime_error("Bad thing happend");
        //직접 오류를 던져 줄수있다.
        throw CustomException();
        //사용자 정의 예외처리 사용
        
    }
    catch (exception & e)
    {
        cerr << e.what() << endl;
        //Exception은 부모 클래스이다.
        //여러 많은 excecption중에 자식중 하나에서 오류가 발생하여 처리가되는것이다.
        
        //정확하게 어느 자식 클래스에서 잡아준것인지 알기 위해서는 typeid를 사용해보면된다.
        cout << typeid(e).name() << endl;
        //length_error출력
        //length_error class에서 발생한 오류이다. 라고 정확하게 파악가능하다.
    }
    catch (length_error & e)
    {
        cout << "Length error" << endl;
        cerr << e.what() << endl;
    }
    return 0;
}
```
## 함수 try
```cpp
// 함수 try

#include <iostream>

using namespace std;
class A
{
private:
    int m_x;
public:
    A(int x) : m_x(x)
    {
        if(x <= 0)
            throw 1;
    }
};

class B : public A
{
public:
//    B(int x) : A(x)
//    {}
    
    //B생성자에서 예외처리 하는방법 - try용법 사용
    B(int x) try : A(x)
    {
        
    }
    catch (...)
    {
        cout << "Catch in B constructor" << endl;
//        throw;
        //throw가 없지만 main에서도 예외처리를 한번더 한다.
        //생성자에서 예외처리를 하는경우
        //throw가 없어도 rethrow를 해준것처럼 작동한다.
    }
};

void doSomething()
try
{
    throw -1;
}
catch(...)
{
    cout << "Catch in doSomething()" << endl;
}
//try문법은 이런식으로 사용한다.
//일반적으로 일반 함수에 대해서는 잘 사용하지않고 - 알아보기 힘듬
//생성자 예외처리에서 많이 사용한다.


int main() {
    //이번에는 try()의 문법에 대해 알아보자
    //생성자에서 발생하는 오류를 처리하는것도 중요하다
    //초기화 리스트에서 발생하는 예외를 처리하는데 많이사용하는 try함수에 대해 알아보자
    
    try {
//        doSomething();
        B b(0);
    } catch (...) {
        cout << "Catch in main()" << endl;
    }
    
    return 0;
}
```
## 예외처리의 위험성과 단점
```cpp
// 예외처리의 위험성과 단점

#include <iostream>
#include <memory>

using namespace std;

class A
{
public:
    ~A()
    {
        throw "error";
    }
};

int main() {
    //이번에는 예외처리의 위험성과 단점에 대해 알아보자
    
    
//    //1. 예외처리할때 메모리 처리가 안되어 메모리 누수 발생
//    //이 단점은 스마트포인터를 사용하면 해결이 된다.
//    try {
//        int *i = new int[1000000];
//
//        unique_ptr<int> up_i(i);
//        //스마트 포인터 사용방법
//        //이것을 사용하면 메모리할당이 영역을 벗어나게 되면, throw를 만나면 알아서 삭제해준다.
//        throw "error";
//
//        delete [] i; //throw가 되면 메모리가 삭제가 안된다.
//    } catch (...) {
//        cout << "Catch" << endl;
//    }
    
    
    //2. 소멸자 안에서 throw를 사용하지 못한다.
//    try {
//        A a;
//    } catch (...) {
//        cout << "Catch" << endl;
//    }
    
    //3. for문에서 예외처리를 반복적으로 하게되면 프로그램이 느려진다.
    //빈번하게 사용되는곳에서 예외처리를 하게되면 느려지게 된다.
    
    
    //4. 모든 오류를 에외처리하려고 하지말것
    //모든 오류에 대해 예외처리를 만들지말고 if를 이용하여 오류를 거르는 작업부터 진행하자
    //
    
    return 0;
}
```